<mujocoinclude>
<!-- =================================================
    Copyright 2018 Vikash Kumar
    Model   :: Franka (MuJoCoV2.0)
    Author  :: Vikash Kumar (vikashplus@gmail.com)
    source  :: https://github.com/vikashplus/robotiq_sim
    License :: Under Apache License, Version 2.0 (the "License"); you may not use this file except in compliance with the License. You may obtain a copy of the License at http://www.apache.org/licenses/LICENSE-2.0 Unless required by applicable law or agreed to in writing, software distributed under the License is distributed on an "AS IS" BASIS, WITHOUT WARRANTIES OR CONDITIONS OF ANY KIND, either express or implied. See the License for the specific language governing permissions and limitations under the License.
====================================================== -->

    <body name="robotiq_2f_85" pos="0 0 0" childclass="robotiq2f85">
        <geom class="robotiq_viz" mesh="robotiq-2f-base" />
        <body name="robotiq_2f_85_right_driver" pos="0 0.0306011 0.054904">
            <inertial pos="0 0.01575 0.05295" quat="0.738425 0.674335 0 0" mass="0.2" diaginertia="0.00043212 0.000431866 0.000360253" />
            <joint name="robotiq_2f_85_right_driver_joint" range="0 0.834" />
            <geom class="robotiq_viz" mesh="robotiq-2f-driver" />
            <geom pos="0 0.0315 -0.0041" class="robotiq_viz" mesh="robotiq-2f-coupler" />
            <geom pos="0 0.0315 -0.0041" type="mesh" mesh="robotiq-2f-coupler" />
            <body name="robotiq_2f_85_right_follower" pos="0 0.0376 0.043">
                <inertial pos="0 0 0.055" quat="0.707107 0.707107 0 0" mass="0.2" diaginertia="0.000380833 0.000380833 0.00036" />
                <joint name="robotiq_2f_85_right_follower_joint" range="-2.96706 2.96706" />
                <geom class="robotiq_viz" mesh="robotiq-2f-follower" />
                <geom type="mesh" mesh="robotiq-2f-pad" rgba="1 1 1 1"/>
            </body>
        </body>
        <body name="robotiq_2f_85_right_spring_link" pos="0 0.012 0.0614">
            <inertial pos="0 0 0.055" quat="0.707107 0.707107 0 0" mass="0.1" diaginertia="0.000190833 0.000190833 0.00018" />
            <joint name="robotiq_2f_85_right_spring_link_joint" range="-2.96706 2.96706" />
            <geom class="robotiq_viz" mesh="robotiq-2f-spring_link" />
            <site type="sphere" size="0.01" pos="0 0.037 0.043" rgba="1 0 0 1" group="3"/>
        </body>
        <body name="robotiq_2f_85_left_driver" pos="0 -0.0306011 0.054904" quat="0 0 0 1">
            <inertial pos="0 0.01575 0.05295" quat="0.738425 0.674335 0 0" mass="0.2" diaginertia="0.00043212 0.000431866 0.000360253" />
            <joint name="robotiq_2f_85_left_driver_joint" range="0 0.834" />
            <geom class="robotiq_viz" mesh="robotiq-2f-driver" />
            <geom pos="0 0.0315 -0.0041" class="robotiq_viz" mesh="robotiq-2f-coupler" />
            <geom pos="0 0.0315 -0.0041" type="mesh" mesh="robotiq-2f-coupler" />
            <body name="robotiq_2f_85_left_follower" pos="0 0.0376 0.043">
                <inertial pos="0 0 0.055" quat="0.707107 0.707107 0 0" mass="0.2" diaginertia="0.000380833 0.000380833 0.00036" />
                <joint name="robotiq_2f_85_left_follower_joint" range="-2.96706 2.96706" />
                <geom class="robotiq_viz" mesh="robotiq-2f-follower" />
                <geom type="mesh" mesh="robotiq-2f-pad" rgba="1 1 1 1"/>
            </body>
        </body>
        <body name="robotiq_2f_85_left_spring_link" pos="0 -0.012 0.0614" quat="0 0 0 1">
            <inertial pos="0 0 0.055" quat="0.707107 0.707107 0 0" mass="0.1" diaginertia="0.000190833 0.000190833 0.00018" />
            <joint name="robotiq_2f_85_left_spring_link_joint" range="-2.96706 2.96706" />
            <geom class="robotiq_viz" mesh="robotiq-2f-spring_link" />
            <site type="sphere" size="0.01" pos="0 0.037 0.043" rgba="1 0 0 1" group="3"/>
        </body>
    </body>
</mujocoinclude>

